Workbook
Name solver_eng: 1
Name solver_neg: 1
Name solver_num: 0
Name solver_opt: 'Solution SOLVEUR-REBALENCEMENT'!$M$17
Name solver_typ: 1
Name solver_val: 0
Name solver_ver: 3

Sheet Details RECAP
B1: AVANT REBALANCEMENT
A3: N° | E3: Mt investi hors commission | F3: Commisions de courtage | G3: Mt Investi | H3: Cours le 31/10 | I3: Cours actuel 24/10 | J3: Valorisation actuelle | K3: Poids dans le PTF | L3: Poids dans le MASI | M3: Performance du titres VENDREDI (w)/ (w-1) dans le PTF | N3: Performance du titres VENDREDI (w)/(w-1) dans le MASI | O3: Contribution de la performance dans le PTF
A4: 1 | B4: IAM | C4: 823 | D4: 120.45 | E4: =D4*C4 -> 99130.35 | F4: =E4*0.44% -> 436.17354 | G4: =E4+F4 -> 99566.524 | H4: 120 | I4: 119.4 | J4: =I4*C4 -> 98266.2 | K4: =J4/$J$19 -> 0.098732772 | L4: 0.073024613 | M4: =(D4/I4)-1 -> 0.0087939698 | N4: =(H4/I4)-1 -> 0.0050251256 | O4: =K4*M4 -> 0.00086825302
A5: 2 | B5: Sothema | C5: 50 | D5: 1795 | E5: =D5*C5 -> 89750 | F5: =E5*0.44% -> 394.9 | G5: =E5+F5 -> 90144.9 | H5: 1840 | I5: 1789 | J5: =I5*C5 -> 89450 | K5: =J5/$J$19 -> 0.089874712 | L5: 0.0053593552 | M5: =(D5/I5)-1 -> 0.003353829 | N5: =(H5/I5)-1 -> 0.028507546 | O5: =K5*M5 -> 0.00030142441
A6: 3 | B6: RISMA | C6: 216 | D6: 416 | E6: =D6*C6 -> 89856 | F6: =E6*0.44% -> 395.3664 | G6: =E6+F6 -> 90251.366 | H6: 419 | I6: 415 | J6: =I6*C6 -> 89640 | K6: =J6/$J$19 -> 0.090065614 | L6: 0.0026871853 | M6: =(D6/I6)-1 -> 0.0024096386 | N6: =(H6/I6)-1 -> 0.0096385542 | O6: =K6*M6 -> 0.00021702558
A7: 4 | B7: Sonasid | C7: 33 | D7: 2410 | E7: =D7*C7 -> 79530 | F7: =E7*0.44% -> 349.932 | G7: =E7+F7 -> 79879.932 | H7: 2500 | I7: 2475 | J7: =I7*C7 -> 81675 | K7: =J7/$J$19 -> 0.082062796 | L7: 0.0098032771 | M7: =(D7/I7)-1 -> -0.026262626 | N7: =(H7/I7)-1 -> 0.01010101 | O7: =K7*M7 -> -0.0021551845
A8: 5 | B8: ATTIJARIWAFA BANK | C8: 128 | D8: 768 | E8: =D8*C8 -> 98304 | F8: =E8*0.44% -> 432.5376 | G8: =E8+F8 -> 98736.538 | H8: 777 | I8: 799.9 | J8: =I8*C8 -> 102387.2 | K8: =J8/$J$19 -> 0.10287334 | L8: 0.17922163 | M8: =(D8/I8)-1 -> -0.039879985 | N8: =(H8/I8)-1 -> -0.028628579 | O8: =K8*M8 -> -0.0041025872
A9: 6 | B9: Sanlam | C9: 46 | D9: 1951 | E9: =D9*C9 -> 89746 | F9: =E9*0.44% -> 394.8824 | G9: =E9+F9 -> 90140.882 | H9: 2000 | I9: 1901 | J9: =I9*C9 -> 87446 | K9: =J9/$J$19 -> 0.087861197 | L9: 0.0015586257 | M9: =(D9/I9)-1 -> 0.026301946 | N9: =(H9/I9)-1 -> 0.052077854 | O9: =K9*M9 -> 0.0023109205
A10: 7 | B10: Marsa maroc | C10: 92 | D10: 975 | E10: =D10*C10 -> 89700 | F10: =E10*0.44% -> 394.68 | G10: =E10+F10 -> 90094.68 | H10: 998 | I10: 985 | J10: =I10*C10 -> 90620 | K10: =J10/$J$19 -> 0.091050267 | L10: 0.081416881 | M10: =(D10/I10)-1 -> -0.010152284 | N10: =(H10/I10)-1 -> 0.01319797 | O10: =K10*M10 -> -0.00092436819
A11: 8 | B11: Ciments du Maroc | C11: 37 | D11: 2003 | E11: =D11*C11 -> 74111 | F11: =E11*0.44% -> 326.0884 | G11: =E11+F11 -> 74437.088 | H11: 2000 | I11: 2020 | J11: =I11*C11 -> 74740 | K11: =J11/$J$19 -> 0.075094868 | L11: 0.046509832 | M11: =(D11/I11)-1 -> -0.0084158416 | N11: =(H11/I11)-1 -> -0.0099009901 | O11: =K11*M11 -> -0.00063198652
A12: 9 | B12: Label vie | C12: 18 | D12: 4698 | E12: =D12*C12 -> 84564 | F12: =E12*0.44% -> 372.0816 | G12: =E12+F12 -> 84936.082 | H12: 4650 | I12: 4690 | J12: =I12*C12 -> 84420 | K12: =J12/$J$19 -> 0.084820829 | L12: 0.019004359 | M12: =(D12/I12)-1 -> 0.0017057569 | N12: =(H12/I12)-1 -> -0.0085287846 | O12: =K12*M12 -> 0.00014468372
A13: 10 | B13: Tgcc | C13: 106 | D13: 931 | E13: =D13*C13 -> 98686 | F13: =E13*0.44% -> 434.2184 | G13: =E13+F13 -> 99120.218 | H13: 961 | I13: 920 | J13: =I13*C13 -> 97520 | K13: =J13/$J$19 -> 0.097983029 | L13: 0.031684414 | M13: =(D13/I13)-1 -> 0.011956522 | N13: =(H13/I13)-1 -> 0.044565217 | O13: =K13*M13 -> 0.0011715362
A14: 11 | B14: HPS | C14: 187 | D14: 528 | E14: =D14*C14 -> 98736 | F14: =E14*0.44% -> 434.4384 | G14: =E14+F14 -> 99170.438 | H14: 0 | I14: 530 | J14: =I14*C14 -> 99110 | K14: =J14/$J$19 -> 0.099580578 | L14: 0.0083459577 | M14: =(D14/I14)-1 -> -0.0037735849 | N14: =(H14/I14)-1 -> -1 | O14: =K14*M14 -> -0.00037577577
A15: 12 | G15: =SUM(G4:G14) -> 996478.65
A16: 13
A17: 14
A18: 15
A19: TOTAL | J19: =SUM(J4:J14) -> 995274.4 | K19: =SUM(K4:K14) -> 1 | L19: =SUM(L4:L14) -> 0.45861613 | M19: =AVERAGE(M4:M14) -> -0.0030875145 | N19: =AVERAGE(N4:N14) -> -0.080358643 | O19: =AVERAGE(O4:O14) -> -0.00028873262
B22: APRES REBALANCEMENT
A24: N° | E24: Mt investi hors commission et frais | F24: Commisions de courtage | G24: Frais de gestion | H24: Mt Investi | I24: Cours le 31/10 | J24: Cours actuel 7/11 | K24: Valorisation actuelle | L24: Poids dans le PTF | M24: Poids dans le MASI | N24: Performance du titres VENDREDI (w)/ (w-1) dans le PTF | O24: Performance du titres VENDREDI (w)/(w-1) dans le MASI | P24: Contribution de la performance dans le PTF
A25: 1 | B25: IAM | C25: 566 | D25: 120.45 | E25: =D25*C25 -> 68174.7 | F25: =E25*0.44% -> 299.96868 | G25: =D25*2% -> 2.409 | H25: =E25+F25 -> 68474.669 | I25: 120 | J25: 115.95 | K25: =J25*C25 -> 65627.7 | L25: =K25/$K$40 -> 0.065513667 | M25: 0.073024613 | N25: =J25/D25-1 -> -0.0373599 | O25: =(J25/I25)-1 -> -0.03375 | P25: =L25*N25 -> -0.0024475841
A26: 2 | B26: Sothema | C26: 57 | D26: =(1795*50+1799*7)/57 -> 1795.4912 | E26: =D26*C26 -> 102343 | F26: =E26*0.44% -> 450.3092 | G26: =D26*2% -> 35.909825 | H26: =E26+F26 -> 102793.31 | I26: 1840 | J26: 1834 | K26: =J26*C26 -> 104538 | L26: =K26/$K$40 -> 0.10435636 | M26: 0.0053593552 | N26: =J26/D26-1 -> 0.021447485 | O26: =(J26/I26)-1 -> -0.0032608696 | P26: =L26*N26 -> 0.0022381815
A27: 3 | B27: RISMA | C27: 253 | D27: =(416*216+394*37)/253 -> 412.78261 | E27: =D27*C27 -> 104434 | F27: =E27*0.44% -> 459.5096 | G27: =D27*2% -> 8.2556522 | H27: =E27+F27 -> 104893.51 | I27: 419 | J27: 419 | K27: =J27*C27 -> 106007 | L27: =K27/$K$40 -> 0.1058228 | M27: 0.0026871853 | N27: =(J27/D27)-1 -> 0.015062145 | O27: =(J27/I27)-1 -> 0 | P27: =L27*N27 -> 0.0015939184
A28: 4 | B28: Sonasid | C28: 41 | D28: =(2410*33+2438*8)/41 -> 2415.4634 | E28: =D28*C28 -> 99034 | F28: =E28*0.44% -> 435.7496 | G28: =D28*2% -> 48.309268 | H28: =E28+F28 -> 99469.75 | I28: 2500 | J28: 2438 | K28: =J28*C28 -> 99958 | L28: =K28/$K$40 -> 0.099784315 | M28: 0.0098032771 | N28: =(J28/D28)-1 -> 0.009330129 | O28: =(J28/I28)-1 -> -0.0248 | P28: =L28*N28 -> 0.00093100054
A29: 5 | B29: ATTIJARIWAFA BANK | C29: 258 | D29: =(768*128+760*130)/258 -> 763.96899 | E29: =D29*C29 -> 197104 | F29: =E29*0.44% -> 867.2576 | G29: =D29*2% -> 15.27938 | H29: =E29+F29 -> 197971.26 | I29: 777 | J29: 766 | K29: =J29*C29 -> 197628 | L29: =K29/$K$40 -> 0.19728461 | M29: 0.17922163 | N29: =(J29/D29)-1 -> 0.002658495 | O29: =(J29/I29)-1 -> -0.014157014 | P29: =L29*N29 -> 0.00052448014
A30: 6 | B30: Sanlam | C30: 50 | D30: =(1951*46+1923*4)/50 -> 1948.76 | E30: =D30*C30 -> 97438 | F30: =E30*0.44% -> 428.7272 | G30: =D30*2% -> 38.9752 | H30: =E30+F30 -> 97866.727 | I30: 2000 | J30: 2000 | K30: =J30*C30 -> 100000 | L30: =K30/$K$40 -> 0.099826242 | M30: 0.0015586257 | N30: =(J30/D30)-1 -> 0.026293643 | O30: =(J30/I30)-1 -> 0 | P30: =L30*N30 -> 0.0026247956
A31: 7 | B31: Marsa maroc | C31: 101 | D31: =(975*92+965.1*9)/101 -> 974.11782 | E31: =D31*C31 -> 98385.9 | F31: =E31*0.44% -> 432.89796 | G31: =D31*2% -> 19.482356 | H31: =E31+F31 -> 98818.798 | I31: 998 | J31: 979.9 | K31: =J31*C31 -> 98969.9 | L31: =K31/$K$40 -> 0.098797932 | M31: 0.081416881 | N31: =(J31/D31)-1 -> 0.0059358099 | O31: =(J31/I31)-1 -> -0.018136273 | P31: =L31*N31 -> 0.00058644575
A32: 8 | B32: Ciments du Maroc | C32: 49 | D32: =(2003*37+2000*12)/49 -> 2002.2653 | E32: =D32*C32 -> 98111 | F32: =E32*0.44% -> 431.6884 | G32: =D32*2% -> 40.045306 | H32: =E32+F32 -> 98542.688 | I32: 2000 | J32: 2000 | K32: =J32*C32 -> 98000 | L32: =K32/$K$40 -> 0.097829718 | M32: 0.046509832 | N32: =(J32/D32)-1 -> -0.0011313716 | O32: =(J32/I32)-1 -> 0 | P32: =L32*N32 -> -0.00011068177
A33: 9 | B33: Label vie | C33: 7 | D33: 4698 | E33: =D33*C33 -> 32886 | F33: =E33*0.44% -> 144.6984 | G33: =D33*2% -> 93.96 | H33: =E33+F33 -> 33030.698 | I33: 4650 | J33: 4646 | K33: =J33*C33 -> 32522 | L33: =K33/$K$40 -> 0.032465491 | M33: 0.019004359 | N33: =(J33/D33)-1 -> -0.01106854 | O33: =(J33/I33)-1 -> -0.00086021505 | P33: =L33*N33 -> -0.00035934557
A34: 10 | B34: Tgcc | C34: 105 | D34: 931 | E34: =D34*C34 -> 97755 | F34: =E34*0.44% -> 430.122 | G34: =D34*2% -> 18.62 | H34: =E34+F34 -> 98185.122 | I34: 961 | J34: 938 | K34: =J34*C34 -> 98490 | L34: =K34/$K$40 -> 0.098318866 | M34: 0.031684414 | N34: =(J34/D34)-1 -> 0.007518797 | O34: =(J34/I34)-1 -> -0.023933403 | P34: =L34*N34 -> 0.0007392396
A35: 11 | B35: HPS | C35: 0 | D35: 0 | E35: =D35*C35 -> 0 | F35: =E35*0.44% -> 0 | H35: =E35+F35 -> 0 | I35: 0 | J35: 0 | K35: =J35*C35 -> 0 | L35: 0 | M35: - | N35: - | O35: - | P35: -
A36: 12 | H36: =SUM(H25:H35) -> 1000046.5
A37: 13
A38: 14
A39: 15
A40: TOTAL | K40: =SUM(K25:K35) -> 1001740.6 | L40: =SUM(L25:L35) -> 1 | M40: =SUM(M25:M35) -> 0.45027017 | N40: =AVERAGE(N25:N35) -> 0.0038686692 | O40: =AVERAGE(O25:O35) -> -0.011889777 | P40: =AVERAGE(P25:P35) -> 0.000632045
B43: APRES SOUSCRIPTION
A46: N° | E46: Mt investi hors commission et frais | F46: Commisions de courtage | G46: Frais de gestion | H46: Cours Ajusté | I46: Mt Investi | J46: Cours le 31/10 | K46: Cours actuel 7/11 | L46: Valorisation actuelle | M46: Poids dans le PTF | N46: Poids dans le MASI | O46: Performance du titres VENDREDI (w)/ (w-1) dans le PTF | P46: Performance du titres VENDREDI (w)/(w-1) dans le MASI | Q46: Contribution de la performance dans le PTF
A47: 1 | B47: IAM | C47: 674 | D47: =(120.45*566+K47*108)/673 -> 119.90684 | E47: =D47*C47 -> 80817.207 | F47: =E47*0.44% -> 355.59571 | G47: =D47*2% -> 2.3981367 | H47: =D47*(1+0.44%) -> 120.43443 | I47: =E47+F47 -> 81172.803 | J47: 120 | K47: 115.95 | L47: =K47*C47 -> 78150.3 | M47: =L47/$L$62 -> 0.065116991 | N47: 0.073024613 | O47: =K47/D47-1 -> -0.032999245 | P47: =(K47/J47)-1 -> -0.03375 | Q47: =M47*O47 -> -0.0021488116
A48: 2 | B48: Sothema | C48: 69 | D48: =(1794.87719298246*57+K48*12)/69 -> 1801.6812 | E48: =D48*C48 -> 124316 | F48: =E48*0.44% -> 546.9904 | G48: =D48*2% -> 36.033623 | H48: =D48*(1+0.44%) -> 1809.6086 | I48: =E48+F48 -> 124862.99 | J48: 1840 | K48: 1834 | L48: =K48*C48 -> 126546 | M48: =L48/$L$62 -> 0.10544163 | N48: 0.0053593552 | O48: =K48/D48-1 -> 0.017938158 | P48: =(K48/J48)-1 -> -0.0032608696 | Q48: =M48*O48 -> 0.0018914285
...

Sheet Masi
AE2: 45933 | AK2: 45940 | AQ2: 45947 | AW2: 45954 | BC2: 45961 | BI2: 45968 | BO2: 45975
B3: ENTREPRISE | C3: Cours 03/10/25 | D3: Cours 10/10/25 | E3: Cours 17/10/25 | F3: Cours 24/10/25 | G3: Cours 31/10/25 | H3: Cours 07/11/25 | I3: Cours 14/11/25 | J3: Nbre de titres | K3: Capitalisation Globale 14/11 | L3: Facteurs flottants | M3: Capitalisation flottante 03/10/25 | N3: Capitalisation flottante 10/10/25 | O3: Capitalisation flottante17/10/25 | P3: Capitalisation flottante 24/10/25 | Q3: Capitalisation flottante 31/10/25 | R3: Capitalisation flottante 07/11/25 | S3: Capitalisation flottante 14/11/25 | T3: poids 03/10/25 | U3: poids 10/10/25 | V3: poids 17/10/25 | W3: poids 24/10/25 | X3: poids 31/10/25 | Y3: poids 07/11/25 | Z3: poids 14/11/25 | AA3: Rnet | AB3: fondspropres | AC3: dividende par action | AD3: BPA | AE3: PER | AF3: PER*POIDS | AG3: PBR | AH3: PBR*POID | AI3: DY | AJ3: DY*POIDS | AK3: PER | AL3: PER*POIDS | AM3: PBR | AN3: PBR*POID | AO3: DY | AP3: DY*POIDS | AQ3: PER | AR3: PER*POIDS | AS3: PBR | AT3: PBR*POID | AU3: DY | AV3: DY*POIDS | AW3: PER | AX3: PER*POIDS | AY3: PBR | AZ3: PBR*POID | BA3: DY | BB3: DY*POIDS | BC3: PER | BD3: PER*POIDS | BE3: PBR | BF3: PBR*POID | BG3: DY | BH3: DY*POIDS | BI3: PER | BJ3: PER*POIDS | BK3: PBR | BL3: PBR*POID | BM3: DY | BN3: DY*POIDS | BO3: PER | BP3: PER*POIDS | BQ3: PBR | BR3: PBR*POID | BS3: DY | BT3: DY*POIDS
A4: 1 | B4: AFMA | C4: 1335 | D4: 1260 | E4: 1260 | F4: 1320 | G4: 1320 | H4: 1335 | I4: 1332 | J4: 1000000 | K4: =I4*J4 -> 1332000000 | L4: 0.4443 | M4: =(C4*J4)*L4 -> 593140500 | N4: =(D4*J4)*L4 -> 559818000 | O4: =(E4*J4)*L4 -> 559818000 | P4: =F4*J4*L4 -> 586476000 | Q4: =G4*J4*L4 -> 586476000 | R4: =H4*J4*L4 -> 593140500 | S4: =I4*J4*L4 -> 591807600 | T4: =M4/$M$81 -> 0.0022693756 | U4: =N4/$N$81 -> 0.0021727142 | V4: =O4/$O$81 -> 0.002180016 | W4: =P4/$P$81 -> 0.0021749759 | X4: =Q4/$Q$81 -> 0.0021535155 | Y4: =R4/$R$81 -> 0.0022189695 | Z4: =S4/$S$81 -> 0.0022911041 | AA4: 72354000 | AB4: 68519000 | AC4: 60 | AD4: =AA4/J4 -> 72.354 | AE4: =C4/AD4 -> 18.450949 | AF4: =AE4*T4 -> 0.041872134 | AG4: =(C4*J4)/AB4 -> 19.483647 | AH4: =AG4*T4 -> 0.044215712 | AI4: =AC4/C4 -> 0.04494382 | AJ4: =AI4*T4 -> 0.00010199441 | AK4: =D4/AD4 -> 17.414379 | AL4: =AK4*U4 -> 0.037836469 | AM4: =(D4*J4)/AB4 -> 18.38906 | AN4: =AM4*U4 -> 0.039954172 | AO4: =AC4/D4 -> 0.047619048 | AP4: =AO4*U4 -> 0.00010346258 | AQ4: =E4/AD4 -> 17.414379 | AR4: =AQ4*V4 -> 0.037963625 | AS4: =(E4*J4)/AB4 -> 18.38906 | AT4: =AS4*V4 -> 0.040088444 | AU4: =AC4/E4 -> 0.047619048 | AV4: =AU4*V4 -> 0.00010381028 | AW4: =F4/AD4 -> 18.243635 | AX4: =AW4*W4 -> 0.039679468 | AY4: =(F4*J4)/AB4 -> 19.264729 | AZ4: =AY4*W4 -> 0.041900323 | BA4: =AC4/F4 -> 0.045454545 | BB4: =BA4*W4 -> 9.8862543e-05 | BC4: =G4/AD4 -> 18.243635 | BD4: =BC4*X4 -> 0.039287951 | BE4: =(G4*J4)/AB4 -> 19.264729 | BF4: =BE4*X4 -> 0.041486893 | BG4: =AC4/G4 -> 0.045454545 | BH4: =BG4*X4 -> 9.7887066e-05 | BI4: =H4/AD4 -> 18.450949 | BJ4: =BI4*Y4 -> 0.040942094 | BK4: =(H4*J4)/AB4 -> 19.483647 | BL4: =BK4*Y4 -> 0.043233618 | BM4: =AC4/H4 -> 0.04494382 | BN4: =BM4*Y4 -> 9.9728967e-05 | BO4: =I4/AD4 -> 18.409487 | BP4: =BO4*Z4 -> 0.04217805 | BQ4: =(I4*J4)/AB4 -> 19.439863 | BR4: =BQ4*Z4 -> 0.04453875 | BS4: =AC4/I4 -> 0.045045045 | BT4: =BS4*Z4 -> 0.00010320289
A5: 2 | B5: AFRIC INDUSTRIES SA | C5: 334 | D5: 328 | E5: 331.55 | F5: 330 | G5: 334.45 | H5: 331 | I5: 334.8 | J5: 291500 | K5: =I5*J5 -> 97594200 | L5: 0.49 | M5: =(C5*J5)*L5 -> 47706890 | N5: =(D5*J5)*L5 -> 46849880 | O5: =(E5*J5)*L5 -> 47356944 | P5: =F5*J5*L5 -> 47135550 | Q5: =G5*J5*L5 -> 47771166 | R5: =H5*J5*L5 -> 47278385 | S5: =I5*J5*L5 -> 47821158 | T5: =M5/$M$81 -> 0.00018252817 | U5: =N5/$N$81 -> 0.00018182945 | V5: =O5/$O$81 -> 0.0001844151 | W5: =P5/$P$81 -> 0.00017480457 | X5: =Q5/$Q$81 -> 0.00017541373 | Y5: =R5/$R$81 -> 0.0001768709 | Z5: =S5/$S$81 -> 0.00018513322 | AA5: 9916766.7 | AB5: 48036443 | AC5: 22 | AD5: =AA5/J5 -> 34.019783 | AE5: =C5/AD5 -> 9.8178169 | AF5: =AE5*T5 -> 0.0017920282 | AG5: =(C5*J5)/AB5 -> 2.0268153 | AH5: =AG5*T5 -> 0.00036995089 | AI5: =AC5/C5 -> 0.065868263 | AJ5: =AI5*T5 -> 1.2022814e-05 | AK5: =D5/AD5 -> 9.641449 | AL5: =AK5*U5 -> 0.0017530994 | AM5: =(D5*J5)/AB5 -> 1.9904055 | AN5: =AM5*U5 -> 0.00036191434 | AO5: =AC5/D5 -> 0.067073171 | AP5: =AO5*U5 -> 1.2195878e-05 | AQ5: =E5/AD5 -> 9.7458 | AR5: =AQ5*V5 -> 0.0017972727 | AS5: =(E5*J5)/AB5 -> 2.011948 | AT5: =AS5*V5 -> 0.0003710336 | AU5: =AC5/E5 -> 0.066354999 | AV5: =AU5*V5 -> 1.2236864e-05 | AW5: =F5/AD5 -> 9.7002383 | AX5: =AW5*W5 -> 0.001695646 | AY5: =(F5*J5)/AB5 -> 2.0025421 | AZ5: =AY5*W5 -> 0.00035005352 | BA5: =AC5/F5 -> 0.066666667 | BB5: =BA5*W5 -> 1.1653638e-05 | BC5: =G5/AD5 -> 9.8310445 | BD5: =BC5*X5 -> 0.0017245002 | BE5: =(G5*J5)/AB5 -> 2.0295461 | BF5: =BE5*X5 -> 0.00035601025 | BG5: =AC5/G5 -> 0.065779638 | BH5: =BG5*X5 -> 1.1538652e-05 | BI5: =H5/AD5 -> 9.7296329 | BJ5: =BI5*Y5 -> 0.001720889 | BK5: =(H5*J5)/AB5 -> 2.0086104 | BL5: =BK5*Y5 -> 0.00035526473 | BM5: =AC5/H5 -> 0.066465257 | BN5: =BM5*Y5 -> 1.175577e-05 | BO5: =I5/AD5 -> 9.8413326 | BP5: =BO5*Z5 -> 0.0018219576 | BQ5: =(I5*J5)/AB5 -> 2.03167 | BR5: =BQ5*Z5 -> 0.00037612962 | BS5: =AC5/I5 -> 0.065710872 | BT5: =BS5*Z5 -> 1.2165266e-05
A6: 3 | B6: AFRIQUIA GAZ | C6: 4100 | D6: 4100 | E6: 4100 | F6: 4139 | G6: 4247 | H6: 4189 | I6: 4160 | J6: 3437500 | K6: =I6*J6 -> 14300000000 | L6: 0.2995 | M6: =(C6*J6)*L6 -> 4221078125 | N6: =(D6*J6)*L6 -> 4221078125 | O6: =(E6*J6)*L6 -> 4221078125 | P6: =F6*J6*L6 -> 4.2612298e+09 | Q6: =G6*J6*L6 -> 4.3724192e+09 | R6: =H6*J6*L6 -> 4.3127064e+09 | S6: =I6*J6*L6 -> 4282850000 | T6: =M6/$M$81 -> 0.016149987 | U6: =N6/$N$81 -> 0.016382461 | V6: =O6/$O$81 -> 0.016437517 | W6: =P6/$P$81 -> 0.015802987 | X6: =Q6/$Q$81 -> 0.016055341 | Y6: =R6/$R$81 -> 0.016134059 | Z6: =S6/$S$81 -> 0.016580482 | AA6: 747392000 | AB6: 3238073000 | AC6: 140 | AD6: =AA6/J6 -> 217.42313 | AE6: =C6/AD6 -> 18.85724 | AF6: =AE6*T6 -> 0.30454418 | AG6: =(C6*J6)/AB6 -> 4.3525115 | AH6: =AG6*T6 -> 0.070293005 | AI6: =AC6/C6 -> 0.034146341 | AJ6: =AI6*T6 -> 0.00055146298 | AK6: =D6/AD6 -> 18.85724 | AL6: =AK6*U6 -> 0.30892799 | AM6: =(D6*J6)/AB6 -> 4.3525115 | AN6: =AM6*U6 -> 0.071304849 | AO6: =AC6/D6 -> 0.034146341 | AP6: =AO6*U6 -> 0.0005594011 | AQ6: =E6/AD6 -> 18.85724 | AR6: =AQ6*V6 -> 0.30996619 | AS6: =(E6*J6)/AB6 -> 4.3525115 | AT6: =AS6*V6 -> 0.071544481 | AU6: =AC6/E6 -> 0.034146341 | AV6: =AU6*V6 -> 0.00056128106 | AW6: =F6/AD6 -> 19.036613 | AX6: =AW6*W6 -> 0.30083535 | AY6: =(F6*J6)/AB6 -> 4.3939134 | AZ6: =AY6*W6 -> 0.069436956 | BA6: =AC6/F6 -> 0.033824595 | BB6: =BA6*W6 -> 0.00053452963 | BC6: =G6/AD6 -> 19.533341 | BD6: =BC6*X6 -> 0.31361445 | BE6: =(G6*J6)/AB6 -> 4.508565 | BF6: =BE6*X6 -> 0.07238655 | BG6: =AC6/G6 -> 0.032964445 | BH6: =BG6*X6 -> 0.00052925543 | BI6: =H6/AD6 -> 19.26658 | BJ6: =BI6*Y6 -> 0.31084814 | BK6: =(H6*J6)/AB6 -> 4.4469929 | BL6: =BK6*Y6 -> 0.071748047 | BM6: =AC6/H6 -> 0.033420864 | BN6: =BM6*Y6 -> 0.00053921421 | BO6: =I6/AD6 -> 19.133199 | BP6: =BO6*Z6 -> 0.31723766 | BQ6: =(I6*J6)/AB6 -> 4.4162068 | BR6: =BQ6*Z6 -> 0.073222836 | BS6: =AC6/I6 -> 0.033653846 | BT6: =BS6*Z6 -> 0.00055799698
A7: 4 | B7: AGMA | C7: 6455 | D7: 6200 | E7: 6571 | F7: 6666 | G7: 6600 | H7: 6600 | I7: 6600 | J7: 200000 | K7: =I7*J7 -> 1320000000 | L7: 0.3154 | M7: =(C7*J7)*L7 -> 407181400 | N7: =(D7*J7)*L7 -> 391096000 | O7: =(E7*J7)*L7 -> 414498680 | P7: =F7*J7*L7 -> 420491280 | Q7: =G7*J7*L7 -> 416328000 | R7: =H7*J7*L7 -> 416328000 | S7: =I7*J7*L7 -> 416328000 | T7: =M7/$M$81 -> 0.0015578898 | U7: =N7/$N$81 -> 0.0015178859 | V7: =O7/$O$81 -> 0.0016141206 | W7: =P7/$P$81 -> 0.0015594132 | X7: =Q7/$Q$81 -> 0.0015287391 | Y7: =R7/$R$81 -> 0.0015575047 | Z7: =S7/$S$81 -> 0.0016117582 | AA7: 66626000 | AB7: 157799000 | AC7: 275 | AD7: =AA7/J7 -> 333.13 | AE7: =C7/AD7 -> 19.37682 | AF7: =AE7*T7 -> 0.030186949 | AG7: =(C7*J7)/AB7 -> 8.1812939 | AH7: =AG7*T7 -> 0.012745554 | AI7: =AC7/C7 -> 0.042602634 | AJ7: =AI7*T7 -> 6.6370207e-05 | AK7: =D7/AD7 -> 18.611353 | AL7: =AK7*U7 -> 0.02824991 | AM7: =(D7*J7)/AB7 -> 7.858098 | AN7: =AM7*U7 -> 0.011927696 | AO7: =AC7/D7 -> 0.044354839 | AP7: =AO7*U7 -> 6.7325583e-05 | AQ7: =E7/AD7 -> 19.725032 | AR7: =AQ7*V7 -> 0.03183858 | AS7: =(E7*J7)/AB7 -> 8.3283164 | AT7: =AS7*V7 -> 0.013442907 | AU7: =AC7/E7 -> 0.041850555 | AV7: =AU7*V7 -> 6.7551842e-05 | AW7: =F7/AD7 -> 20.010206 | AX7: =AW7*W7 -> 0.03120418 | AY7: =(F7*J7)/AB7 -> 8.4487227 | AZ7: =AY7*W7 -> 0.01317505 | BA7: =AC7/F7 -> 0.041254125 | BB7: =BA7*W7 -> 6.4332228e-05 | BC7: =G7/AD7 -> 19.812085 | BD7: =BC7*X7 -> 0.030287509 | BE7: =(G7*J7)/AB7 -> 8.365072 | BF7: =BE7*X7 -> 0.012788013 | BG7: =AC7/G7 -> 0.041666667 | BH7: =BG7*X7 -> 6.3697462e-05 | BI7: =H7/AD7 -> 19.812085 | BJ7: =BI7*Y7 -> 0.030857417 | BK7: =(H7*J7)/AB7 -> 8.365072 | BL7: =BK7*Y7 -> 0.013028639 | BM7: =AC7/H7 -> 0.041666667 | BN7: =BM7*Y7 -> 6.4896031e-05 | BO7: =I7/AD7 -> 19.812085 | BP7: =BO7*Z7 -> 0.031932292 | BQ7: =(I7*J7)/AB7 -> 8.365072 | BR7: =BQ7*Z7 -> 0.013482474 | BS7: =AC7/I7 -> 0.041666667 | BT7: =BS7*Z7 -> 6.7156593e-05
A8: 5 | B8: AKDITAL | C8: 1373 | D8: 1285 | E8: 1235 | F8: 1370 | G8: 1440 | H8: 1390 | I8: 1330 | J8: 14159207 | K8: =I8*J8 -> 18831745310 | L8: 0.4524 | M8: =(C8*J8)*L8 -> 8.7949235e+09 | N8: =(D8*J8)*L8 -> 8.2312284e+09 | O8: =(E8*J8)*L8 -> 7.9109472e+09 | P8: =F8*J8*L8 -> 8.7757066e+09 | Q8: =G8*J8*L8 -> 9.2241004e+09 | R8: =H8*J8*L8 -> 8.9038191e+09 | S8: =I8*J8*L8 -> 8.5194816e+09 | T8: =M8/$M$81 -> 0.033649674 | U8: =N8/$N$81 -> 0.031946288 | V8: =O8/$O$81 -> 0.030806425 | W8: =P8/$P$81 -> 0.032545152 | X8: =Q8/$Q$81 -> 0.033870513 | Y8: =R8/$R$81 -> 0.033309651 | Z8: =S8/$S$81 -> 0.032982035 | AA8: 347553992 | AB8: 2638508203 | AC8: 10 | AD8: =AA8/J8 -> 24.546148 | AE8: =C8/AD8 -> 55.935457 | AF8: =AE8*T8 -> 1.8822099 | AG8: =(C8*J8)/AB8 -> 7.3680238 | AH8: =AG8*T8 -> 0.2479316 | AI8: =AC8/C8 -> 0.0072833212 | AJ8: =AI8*T8 -> 0.00024508138 | AK8: =D8/AD8 -> 52.350373 | AL8: =AK8*U8 -> 1.6724001 | AM8: =(D8*J8)/AB8 -> 6.8957834 | AN8: =AM8*U8 -> 0.22029468 | AO8: =AC8/D8 -> 0.0077821012 | AP8: =AO8*U8 -> 0.00024860924 | AQ8: =E8/AD8 -> 50.313393 | AR8: =AQ8*V8 -> 1.5499758 | AS8: =(E8*J8)/AB8 -> 6.627465 | AT8: =AS8*V8 -> 0.2041685 | AU8: =AC8/E8 -> 0.008097166 | AV8: =AU8*V8 -> 0.00024944474 | AW8: =F8/AD8 -> 55.813238 | AX8: =AW8*W8 -> 1.8164503 | AY8: =(F8*J8)/AB8 -> 7.3519247 | AZ8: =AY8*W8 -> 0.23926951 | BA8: =AC8/F8 -> 0.0072992701 | BB8: =BA8*W8 -> 0.00023755586 | BC8: =G8/AD8 -> 58.665009 | BD8: =BC8*X8 -> 1.9870139 | BE8: =(G8*J8)/AB8 -> 7.7275705 | BF8: =BE8*X8 -> 0.26173677 | BG8: =AC8/G8 -> 0.0069444444 | BH8: =BG8*X8 -> 0.00023521189 | BI8: =H8/AD8 -> 56.62803 | BJ8: =BI8*Y8 -> 1.8862599 | BK8: =(H8*J8)/AB8 -> 7.4592521 | BL8: =BK8*Y8 -> 0.24846508 | BM8: =AC8/H8 -> 0.0071942446 | BN8: =BM8*Y8 -> 0.00023963778 | BO8: =I8/AD8 -> 54.183654 | BP8: =BO8*Z8 -> 1.7870872 | BQ8: =(I8*J8)/AB8 -> 7.1372699 | BR8: =BQ8*Z8 -> 0.23540169 | BS8: =AC8/I8 -> 0.007518797 | BT8: =BS8*Z8 -> 0.00024798522
A9: 6 | B9: ALLIANCES | C9: 510 | D9: 515 | E9: 519 | F9: 560 | G9: 617.9 | H9: 618.1 | I9: 595 | J9: 22078588 | K9: =I9*J9 -> 13136759860 | L9: 0.38 | M9: =(C9*J9)*L9 -> 4.2788304e+09 | N9: =(D9*J9)*L9 -> 4.3207797e+09 | O9: =(E9*J9)*L9 -> 4.3543391e+09 | P9: =F9*J9*L9 -> 4.6983235e+09 | Q9: =G9*J9*L9 -> 5.1840966e+09 | R9: =H9*J9*L9 -> 5.1857746e+09 | S9: =I9*J9*L9 -> 4.9919687e+09 | T9: =M9/$M$81 -> 0.016370949 | U9: =N9/$N$81 -> 0.016769413 | V9: =O9/$O$81 -> 0.016956455 | W9: =P9/$P$81 -> 0.017423971 | X9: =Q9/$Q$81 -> 0.019035787 | Y9: =R9/$R$81 -> 0.019400253 | Z9: =S9/$S$81 -> 0.01932574 | AA9: 301915000 | AB9: 3668286000 | AC9: 3.6 | AD9: =AA9/J9 -> 13.674561 | AE9: =C9/AD9 -> 37.29553 | AF9: =AE9*T9 -> 0.61056322 | AG9: =(C9*J9)/AB9 -> 3.0695752 | AH9: =AG9*T9 -> 0.05025186 | AI9: =AC9/C9 -> 0.0070588235 | AJ9: =AI9*T9 -> 0.00011555964 | AK9: =D9/AD9 -> 37.661172 | AL9: =AK9*U9 -> 0.63155576 | AM9: =(D9*J9)/AB9 -> 3.0996691 | AN9: =AM9*U9 -> 0.051979632 | AO9: =AC9/D9 -> 0.0069902913 | AP9: =AO9*U9 -> 0.00011722308 | AQ9: =E9/AD9 -> 37.953686 | AR9: =AQ9*V9 -> 0.64355998 | AS9: =(E9*J9)/AB9 -> 3.1237442 | AT9: =AS9*V9 -> 0.052967629 | AU9: =AC9/E9 -> 0.0069364162 | AV9: =AU9*V9 -> 0.00011761703 | AW9: =F9/AD9 -> 40.951954 | AX9: =AW9*W9 -> 0.71354565 | AY9: =(F9*J9)/AB9 -> 3.370514 | AZ9: =AY9*W9 -> 0.058727737 | BA9: =AC9/F9 -> 0.0064285714 | BB9: =BA9*W9 -> 0.00011201124 | BC9: =G9/AD9 -> 45.186094 | BD9: =BC9*X9 -> 0.86015286 | BE9: =(G9*J9)/AB9 -> 3.7190011 | BF9: =BE9*X9 -> 0.070794112 | BG9: =AC9/G9 -> 0.0058261855 | BH9: =BG9*X9 -> 0.00011090603 | BI9: =H9/AD9 -> 45.20072 | BJ9: =BI9*Y9 -> 0.87690539 | BK9: =(H9*J9)/AB9 -> 3.7202048 | BL9: =BK9*Y9 -> 0.072172914 | BM9: =AC9/H9 -> 0.0058243003 | BN9: =BM9*Y9 -> 0.0001129929 | BO9: =I9/AD9 -> 43.511451 | BP9: =BO9*Z9 -> 0.840891 | BQ9: =(I9*J9)/AB9 -> 3.5811711 | BR9: =BQ9*Z9 -> 0.069208782 | BS9: =AC9/I9 -> 0.0060504202 | BT9: =BS9*Z9 -> 0.00011692885
A10: 7 | B10: ALUMINIUM DU MAROC | C10: 1818 | D10: 1781 | E10: 1814 | F10: 1846 | G10: 1849 | H10: 1867 | I10: 1860 | J10: 465954 | K10: =I10*J10 -> 866674440 | L10: 0.6219 | M10: =(C10*J10)*L10 -> 5.2681421e+08 | N10: =(D10*J10)*L10 -> 5.1609247e+08 | O10: =(E10*J10)*L10 -> 5.256551e+08 | P10: =F10*J10*L10 -> 5.3492796e+08 | Q10: =G10*J10*L10 -> 5.3579729e+08 | R10: =H10*J10*L10 -> 5.4101327e+08 | S10: =I10*J10*L10 -> 5.3898483e+08 | T10: =M10/$M$81 -> 0.0020156089 | U10: =N10/$N$81 -> 0.0020030107 | V10: =O10/$O$81 -> 0.0020469805 | W10: =P10/$P$81 -> 0.0019838074 | X10: =Q10/$Q$81 -> 0.0019674253 | Y10: =R10/$R$81 -> 0.0020239588 | Z10: =S10/$S$81 -> 0.0020866078 | AA10: 36840000 | AB10: 270960000 | AC10: 100 | AD10: =AA10/J10 -> 79.063599 | AE10: =C10/AD10 -> 22.994147 | AF10: =AE10*T10 -> 0.046347208 | AG10: =(C10*J10)/AB10 -> 3.1263078 | AH10: =AG10*T10 -> 0.006301414 | AI10: =AC10/C10 -> 0.055005501 | AJ10: =AI10*T10 -> 0.00011086958 | AK10: =D10/AD10 -> 22.526169 | AL10: =AK10*U10 -> 0.045120158 | AM10: =(D10*J10)/AB10 -> 3.0626811 | AN10: =AM10*U10 -> 0.006134583 | AO10: =AC10/D10 -> 0.056148231 | AP10: =AO10*U10 -> 0.00011246551 | AQ10: =E10/AD10 -> 22.943555 | AR10: =AQ10*V10 -> 0.046965009 | AS10: =(E10*J10)/AB10 -> 3.1194293 | AT10: =AS10*V10 -> 0.0063854108 | AU10: =AC10/E10 -> 0.055126792 | AV10: =AU10*V10 -> 0.00011284347 | AW10: =F10/AD10 -> 23.348292 | AX10: =AW10*W10 -> 0.046318515 | AY10: =(F10*J10)/AB10 -> 3.1744578 | AZ10: =AY10*W10 -> 0.006297513 | BA10: =AC10/F10 -> 0.054171181 | BB10: =BA10*W10 -> 0.00010746519 | BC10: =G10/AD10 -> 23.386236 | BD10: =BC10*X10 -> 0.046010674 | BE10: =(G10*J10)/AB10 -> 3.1796167 | BF10: =BE10*X10 -> 0.0062556585 | BG10: =AC10/G10 -> 0.054083288 | BH10: =BG10*X10 -> 0.00010640483 | BI10: =H10/AD10 -> 23.613901 | BJ10: =BI10*Y10 -> 0.047793564 | BK10: =(H10*J10)/AB10 -> 3.2105703 | BL10: =BK10*Y10 -> 0.0064980621 | BM10: =AC10/H10 -> 0.053561864 | BN10: =BM10*Y10 -> 0.00010840701 | BO10: =I10/AD10 -> 23.525365 | BP10: =BO10*Z10 -> 0.049088209 | BQ10: =(I10*J10)/AB10 -> 3.1985328 | BR10: =BQ10*Z10 -> 0.0066740834 | BS10: =AC10/I10 -> 0.053763441 | BT10: =BS10*Z10 -> 0.00011218321
A11: 8 | B11: ARADEI CAPITAL | C11: 468 | D11: 468 | E11: 462 | F11: 470 | G11: 460 | H11: 460 | I11: 453.9 | J11: 12568130 | K11: =I11*J11 -> 5704674207 | L11: 0.499 | M11: =(C11*J11)*L11 -> 2.9350605e+09 | N11: =(D11*J11)*L11 -> 2.9350605e+09 | O11: =(E11*J11)*L11 -> 2.8974316e+09 | P11: =F11*J11*L11 -> 2.9476035e+09 | Q11: =G11*J11*L11 -> 2.8848886e+09 | R11: =H11*J11*L11 -> 2.8848886e+09 | S11: =I11*J11*L11 -> 2.8466324e+09 | T11: =M11/$M$81 -> 0.011229641 | U11: =N11/$N$81 -> 0.011391287 | V11: =O11/$O$81 -> 0.011283037 | W11: =P11/$P$81 -> 0.010931337 | X11: =Q11/$Q$81 -> 0.010593191 | Y11: =R11/$R$81 -> 0.010792518 | Z11: =S11/$S$81 -> 0.011020357 | AA11: 297453000 | AB11: 5191827000 | AC11: 22 | AD11: =AA11/J11 -> 23.667244 | AE11: =C11/AD11 -> 19.774165 | AF11: =AE11*T11 -> 0.22205677 | AG11: =(C11*J11)/AB11 -> 1.1329123 | AH11: =AG11*T11 -> 0.012722198 | AI11: =AC11/C11 -> 0.047008547 | AJ11: =AI11*T11 -> 0.00052788909 | AK11: =D11/AD11 -> 19.774165 | AL11: =AK11*U11 -> 0.2252532 | AM11: =(D11*J11)/AB11 -> 1.1329123 | AN11: =AM11*U11 -> 0.01290533 | AO11: =AC11/D11 -> 0.047008547 | AP11: =AO11*U11 -> 0.00053548787 | AQ11: =E11/AD11 -> 19.520651 | AR11: =AQ11*V11 -> 0.22025222 | AS11: =(E11*J11)/AB11 -> 1.1183878 | AT11: =AS11*V11 -> 0.012618811 | AU11: =AC11/E11 -> 0.047619048 | AV11: =AU11*V11 -> 0.00053728746 | AW11: =F11/AD11 -> 19.85867 | AX11: =AW11*W11 -> 0.21708182 | AY11: =(F11*J11)/AB11 -> 1.1377538 | AZ11: =AY11*W11 -> 0.012437171 | BA11: =AC11/F11 -> 0.046808511 | BB11: =BA11*W11 -> 0.0005116796 | BC11: =G11/AD11 -> 19.436146 | BD11: =BC11*X11 -> 0.2058908 | BE11: =(G11*J11)/AB11 -> 1.1135463 | BF11: =BE11*X11 -> 0.011796008 | BG11: =AC11/G11 -> 0.047826087 | BH11: =BG11*X11 -> 0.00050663086 | BI11: =H11/AD11 -> 19.436146 | BJ11: =BI11*Y11 -> 0.20976496 | BK11: =(H11*J11)/AB11 -> 1.1135463 | BL11: =BK11*Y11 -> 0.012017969 | BM11: =AC11/H11 -> 0.047826087 | BN11: =BM11*Y11 -> 0.00051616392 | BO11: =I11/AD11 -> 19.178405 | BP11: =BO11*Z11 -> 0.21135288 | BQ11: =(I11*J11)/AB11 -> 1.0987797 | BR11: =BQ11*Z11 -> 0.012108945 | BS11: =AC11/I11 -> 0.048468826 | BT11: =BS11*Z11 -> 0.00053414377
A12: 9 | B12: ATLANTASANAD | C12: 147 | D12: 150.2 | E12: 142.6 | F12: 155.9 | G12: 152 | H12: 150 | I12: 144.4 | J12: 60283595 | K12: =I12*J12 -> 8704951118 | L12: 0.13 | M12: =(C12*J12)*L12 -> 1.1520195e+09 | N12: =(D12*J12)*L12 -> 1.1770975e+09 | O12: =(E12*J12)*L12 -> 1.1175373e+09 | P12: =F12*J12*L12 -> 1.2217676e+09 | Q12: =G12*J12*L12 -> 1.1912038e+09 | R12: =H12*J12*L12 -> 1.1755301e+09 | S12: =I12*J12*L12 -> 1.1316436e+09 | T12: =M12/$M$81 -> 0.0044076655 | U12: =N12/$N$81 -> 0.0045684426 | V12: =O12/$O$81 -> 0.0043518592 | W12: =P12/$P$81 -> 0.0045309871 | X12: =Q12/$Q$81 -> 0.0043740509 | Y12: =R12/$R$81 -> 0.0043977194 | Z12: =S12/$S$81 -> 0.0043810072 | AA12: 453359000 | AB12: 2367775000 | AC12: 5.8 | AD12: =AA12/J12 -> 7.5204374 | AE12: =C12/AD12 -> 19.546736 | AF12: =AE12*T12 -> 0.086155471 | AG12: =(C12*J12)/AB12 -> 3.7426227 | AH12: =AG12*T12 -> 0.016496229 | AI12: =AC12/C12 -> 0.039455782 | AJ12: =AI12*T12 -> 0.00017390789 | AK12: =D12/AD12 -> 19.972243 | AL12: =AK12*U12 -> 0.091242045 | AM12: =(D12*J12)/AB12 -> 3.8240948 | AN12: =AM12*U12 -> 0.017470158 | AO12: =AC12/D12 -> 0.03861518 | AP12: =AO12*U12 -> 0.00017641123 | AQ12: =E12/AD12 -> 18.961663 | AR12: =AQ12*V12 -> 0.082518489 | AS12: =(E12*J12)/AB12 -> 3.6305986 | AT12: =AS12*V12 -> 0.015799854 | AU12: =AC12/E12 -> 0.040673212 | AV12: =AU12*V12 -> 0.00017700409 | AW12: =F12/AD12 -> 20.730177 | AX12: =AW12*W12 -> 0.093928166 | AY12: =(F12*J12)/AB12 -> 3.9692169 | AZ12: =AY12*W12 -> 0.01798447 | BA12: =AC12/F12 -> 0.037203335 | BB12: =BA12*W12 -> 0.00016856783 | BC12: =G12/AD12 -> 20.21159 | BD12: =BC12*X12 -> 0.088406526 | BE12: =(G12*J12)/AB12 -> 3.8699228 | BF12: =BE12*X12 -> 0.016927239 | BG12: =AC12/G12 -> 0.038157895 | BH12: =BG12*X12 -> 0.00016690457 | BI12: =H12/AD12 -> 19.945648 | BJ12: =BI12*Y12 -> 0.087715365 | BK12: =(H12*J12)/AB12 -> 3.8190028 | BL12: =BK12*Y12 -> 0.016794902 | BM12: =AC12/H12 -> 0.038666667 | BN12: =BM12*Y12 -> 0.00017004515 | BO12: =I12/AD12 -> 19.201011 | BP12: =BO12*Z12 -> 0.084119767 | BQ12: =(I12*J12)/AB12 -> 3.6764267 | BR12: =BQ12*Z12 -> 0.016106452 | BS12: =AC12/I12 -> 0.040166205 | BT12: =BS12*Z12 -> 0.00017596843
A13: 10 | B13: ATTIJARIWAFA BANK | C13: 740 | D13: 730 | E13: 728 | F13: 779.9 | G13: 777 | H13: 766 | I13: 736 | J13: 215140839 | K13: =I13*J13 -> 158343657504 | L13: 0.2907 | M13: =(C13*J13)*L13 -> 4.6280667e+10 | N13: =(D13*J13)*L13 -> 4.5655253e+10 | O13: =(E13*J13)*L13 -> 4.553017e+10 | P13: =F13*J13*L13 -> 4.8776071e+10 | Q13: =G13*J13*L13 -> 4.85947e+10 | R13: =H13*J13*L13 -> 4.7906744e+10 | S13: =I13*J13*L13 -> 4.6030501e+10 | T13: =M13/$M$81 -> 0.17707139 | U13: =N13/$N$81 -> 0.17719297 | V13: =O13/$O$81 -> 0.17730137 | W13: =P13/$P$81 -> 0.18088853 | X13: =Q13/$Q$81 -> 0.17843772 | Y13: =R13/$R$81 -> 0.17922163 | Z13: =S13/$S$81 -> 0.17820094 | AA13: 9504486000 | AB13: 72502834000 | AC13: 19 | AD13: =AA13/J13 -> 44.177972 | AE13: =C13/AD13 -> 16.750429 | AF13: =AE13*T13 -> 2.9660218 | AG13: =(C13*J13)/AB13 -> 2.1958345 | AH13: =AG13*T13 -> 0.38881946 | AI13: =AC13/C13 -> 0.025675676 | AJ13: =AI13*T13 -> 0.0045464276 | AK13: =D13/AD13 -> 16.524072 | AL13: =AK13*U13 -> 2.9279495 | AM13: =(D13*J13)/AB13 -> 2.166161 | AN13: =AM13*U13 -> 0.38382851 | AO13: =AC13/D13 -> 0.026027397 | AP13: =AO13*U13 -> 0.0046118719 | AQ13: =E13/AD13 -> 16.478801 | AR13: =AQ13*V13 -> 2.9217139 | AS13: =(E13*J13)/AB13 -> 2.1602263 | AT13: =AS13*V13 -> 0.38301108 | AU13: =AC13/E13 -> 0.026098901 | AV13: =AU13*V13 -> 0.0046273709 | AW13: =F13/AD13 -> 17.653594 | AX13: =AW13*W13 -> 3.1933327 | AY13: =(F13*J13)/AB13 -> 2.3142315 | AZ13: =AY13*W13 -> 0.41861792 | BA13: =AC13/F13 -> 0.024362098 | BB13: =BA13*W13 -> 0.004406824 | BC13: =G13/AD13 -> 17.587951 | BD13: =BC13*X13 -> 3.1383538 | BE13: =(G13*J13)/AB13 -> 2.3056262 | BF13: =BE13*X13 -> 0.41141067 | BG13: =AC13/G13 -> 0.024453024 | BH13: =BG13*X13 -> 0.0043633419 | BI13: =H13/AD13 -> 17.338958 | BJ13: =BI13*Y13 -> 3.1075163 | BK13: =(H13*J13)/AB13 -> 2.2729854 | BL13: =BK13*Y13 -> 0.40736814 | BM13: =AC13/H13 -> 0.024804178 | BN13: =BM13*Y13 -> 0.0044454451 | BO13: =I13/AD13 -> 16.659886 | BP13: =BO13*Z13 -> 2.9688074 | BQ13: =(I13*J13)/AB13 -> 2.1839651 | BR13: =BQ13*Z13 -> 0.38918462 | BS13: =AC13/I13 -> 0.025815217 | BT13: =BS13*Z13 -> 0.0046002959
A14: 11 | B14: AUTO HALL | C14: 95 | D14: 96.38 | E14: 95 | F14: 98.9 | G14: 96 | H14: 95.99 | I14: 94.49 | J14: 50294528 | K14: =I14*J14 -> 4.75233e+09 | L14: 0.3292 | M14: =(C14*J14)*L14 -> 1.5729111e+09 | N14: =(D14*J14)*L14 -> 1.5957597e+09 | O14: =(E14*J14)*L14 -> 1.5729111e+09 | P14: =F14*J14*L14 -> 1.6374832e+09 | Q14: =G14*J14*L14 -> 1.589468e+09 | R14: =H14*J14*L14 -> 1.5893025e+09 | S14: =I14*J14*L14 -> 1.564467e+09 | T14: =M14/$M$81 -> 0.0060180108 | U14: =N14/$N$81 -> 0.0061933159 | V14: =O14/$O$81 -> 0.0061251536 | W14: =P14/$P$81 -> 0.0060726894 | X14: =Q14/$Q$81 -> 0.0058364604 | Y14: =R14/$R$81 -> 0.0059456633 | Z14: =S14/$S$81 -> 0.0060566251 | AA14: 17092037 | AB14: 1.4585141e+09 | AC14: 2 | AD14: =AA14/J14 -> 0.3398389 | AE14: =C14/AD14 -> 279.54422 | AF14: =AE14*T14 -> 1.6823001 | AG14: =(C14*J14)/AB14 -> 3.2759232 | AH14: =AG14*T14 -> 0.019714541 | AI14: =AC14/C14 -> 0.021052632 | AJ14: =AI14*T14 -> 0.00012669496 | AK14: =D14/AD14 -> 283.60496 | AL14: =AK14*U14 -> 1.7564551 | AM14: =(D14*J14)/AB14 -> 3.3235103 | AN14: =AM14*U14 -> 0.020583549 | AO14: =AC14/D14 -> 0.020751193 | AP14: =AO14*U14 -> 0.00012851869 | AQ14: =E14/AD14 -> 279.54422 | AR14: =AQ14*V14 -> 1.7122513 | AS14: =(E14*J14)/AB14 -> 3.2759232 | AT14: =AS14*V14 -> 0.020065533 | AU14: =AC14/E14 -> 0.021052632 | AV14: =AU14*V14 -> 0.0001289506 | AW14: =F14/AD14 -> 291.02024 | AX14: =AW14*W14 -> 1.7672755 | AY14: =(F14*J14)/AB14 -> 3.4104085 | AZ14: =AY14*W14 -> 0.020710352 | BA14: =AC14/F14 -> 0.020222447 | BB14: =BA14*W14 -> 0.00012280464 | BC14: =G14/AD14 -> 282.48679 | BD14: =BC14*X14 -> 1.648723 | BE14: =(G14*J14)/AB14 -> 3.3104066 | BF14: =BE14*X14 -> 0.019321057 | BG14: =AC14/G14 -> 0.020833333 | BH14: =BG14*X14 -> 0.00012159293 | BI14: =H14/AD14 -> 282.45736 | BJ14: =BI14*Y14 -> 1.6793964 | BK14: =(H14*J14)/AB14 -> 3.3100618 | BL14: =BK14*Y14 -> 0.019680513 | BM14: =AC14/H14 -> 0.020835504 | BN14: =BM14*Y14 -> 0.00012388089 | BO14: =I14/AD14 -> 278.0435 | BP14: =BO14*Z14 -> 1.6840053 | BQ14: =(I14*J14)/AB14 -> 3.2583367 | BR14: =BQ14*Z14 -> 0.019734524 | BS14: =AC14/I14 -> 0.021166261 | BT14: =BS14*Z14 -> 0.00012819611
A15: 12 | B15: AUTO NEJMA | C15: 3285 | D15: 3680 | E15: 4122 | F15: 4601 | G15: 4850 | H15: 4875 | I15: 4700 | J15: 1023264 | K15: =I15*J15 -> 4809340800 | L15: 0.0324 | M15: =(C15*J15)*L15 -> 1.0891008e+08 | N15: =(D15*J15)*L15 -> 1.2200581e+08 | O15: =(E15*J15)*L15 -> 1.3665977e+08 | P15: =F15*J15*L15 -> 1.5254042e+08 | Q15: =G15*J15*L15 -> 1.607957e+08 | R15: =H15*J15*L15 -> 1.6162455e+08 | S15: =I15*J15*L15 -> 1.5582264e+08 | T15: =M15/$M$81 -> 0.00041669364 | U15: =N15/$N$81 -> 0.00047351776 | V15: =O15/$O$81 -> 0.00053217382 | W15: =P15/$P$81 -> 0.00056570387 | X15: =Q15/$Q$81 -> 0.00059043514 | Y15: =R15/$R$81 -> 0.00060464586 | Z15: =S15/$S$81 -> 0.00060324654 | AA15: 205383000 | AB15: 1257646000 | AC15: 120 | AD15: =AA15/J15 -> 200.7136 | AE15: =C15/AD15 -> 16.366604 | AF15: =AE15*T15 -> 0.0068198598 | AG15: =(C15*J15)/AB15 -> 2.6727889 | AH15: =AG15*T15 -> 0.0011137341 | AI15: =AC15/C15 -> 0.03652968 | AJ15: =AI15*T15 -> 1.5221685e-05 | AK15: =D15/AD15 -> 18.334582 | AL15: =AK15*U15 -> 0.0086817503 | AM15: =(D15*J15)/AB15 -> 2.9941744 | AN15: =AM15*U15 -> 0.0014177948 | AO15: =AC15/D15 -> 0.032608696 | AP15: =AO15*U15 -> 1.5440796e-05 | AQ15: =E15/AD15 -> 20.536725 | AR15: =AQ15*V15 -> 0.010929108 | AS15: =(E15*J15)/AB15 -> 3.3538008 | AT15: =AS15*V15 -> 0.001784805 | AU15: =AC15/E15 -> 0.029112082 | AV15: =AU15*V15 -> 1.5492688e-05 | AW15: =F15/AD15 -> 22.92321 | AX15: =AW15*W15 -> 0.012967749 | AY15: =(F15*J15)/AB15 -> 3.7435317 | AZ15: =AY15*W15 -> 0.0021177304 | BA15: =AC15/F15 -> 0.026081287 | BB15: =BA15*W15 -> 1.4754285e-05 | BC15: =G15/AD15 -> 24.163784 | BD15: =BC15*X15 -> 0.014267147 | BE15: =(G15*J15)/AB15 -> 3.9461267 | BF15: =BE15*X15 -> 0.0023299318 | BG15: =AC15/G15 -> 0.024742268 | BH15: =BG15*X15 -> 1.4608704e-05 | BI15: =H15/AD15 -> 24.288339 | BJ15: =BI15*Y15 -> 0.014685844 | BK15: =(H15*J15)/AB15 -> 3.9664675 | BL15: =BK15*Y15 -> 0.0023983082 | BM15: =AC15/H15 -> 0.024615385 | BN15: =BM15*Y15 -> 1.488359e-05 | BO15: =I15/AD15 -> 23.41645 | BP15: =BO15*Z15 -> 0.014125893 | BQ15: =(I15*J15)/AB15 -> 3.8240815 | BR15: =BQ15*Z15 -> 0.0023068639 | BS15: =AC15/I15 -> 0.025531915 | BT15: =BS15*Z15 -> 1.5402039e-05
... A80: 77 | B80: ZELLIDJA S.A | C80: 215.3 | D80: 215.35 | E80: 228 | F80: 218 | G80: 214 | H80: 214 | I80: 235 | J80: 57284900 | K80: =I80*J80 -> 13461951500 | L80: 0.1 | M80: =(C80*J80)*L80 -> 1233343897 | N80: =(D80*J80)*L80 -> 1.2336303e+09 | O80: =(E80*J80)*L80 -> 1306095720 | P80: =F80*J80*L80 -> 1248810820 | Q80: =G80*J80*L80 -> 1225896860 | R80: =H80*J80*L80 -> 1225896860 | S80: =I80*J80*L80 -> 1346195150 | T80: =M80/$M$81 -> 0.0047188153 | U80: =N80/$N$81 -> 0.0047878527 | V80: =O80/$O$81 -> 0.0050861343 | W80: =P80/$P$81 -> 0.0046312782 | X80: =Q80/$Q$81 -> 0.0045014422 | Y80: =R80/$R$81 -> 0.004586144 | Z80: =S80/$S$81 -> 0.0052116147 | AA80: 6315000 | AB80: 56572000 | AC80: 20 | AD80: =AA80/J80 -> 0.11023847 | AE80: =C80/AD80 -> 1953.0386 | AF80: =AE80*T80 -> 9.2160287 | AG80: =(C80*J80)/AB80 -> 218.01313 | AH80: =AG80*T80 -> 1.0287637 | AI80: =AC80/C80 -> 0.092893637 | AJ80: =AI80*T80 -> 0.00043834792 | AK80: =D80/AD80 -> 1953.4922 | AL80: =AK80*U80 -> 9.3530329 | AM80: =(D80*J80)/AB80 -> 218.06376 | AN80: =AM80*U80 -> 1.0440572 | AO80: =AC80/D80 -> 0.092872069 | AP80: =AO80*U80 -> 0.00044465779 | AQ80: =E80/AD80 -> 2068.2434 | AR80: =AQ80*V80 -> 10.519364 | AS80: =(E80*J80)/AB80 -> 230.87317 | AT80: =AS80*V80 -> 1.174252 | AU80: =AC80/E80 -> 0.087719298 | AV80: =AU80*V80 -> 0.00044615213 | AW80: =F80/AD80 -> 1977.531 | AX80: =AW80*W80 -> 9.1584961 | AY80: =(F80*J80)/AB80 -> 220.74716 | AZ80: =AY80*W80 -> 1.0223415 | BA80: =AC80/F80 -> 0.091743119 | BB80: =BA80*W80 -> 0.00042488791 | BC80: =G80/AD80 -> 1941.246 | BD80: =BC80*X80 -> 8.7384068 | BE80: =(G80*J80)/AB80 -> 216.69675 | BF80: =BE80*X80 -> 0.97544791 | BG80: =AC80/G80 -> 0.093457944 | BH80: =BG80*X80 -> 0.00042069554 | BI80: =H80/AD80 -> 1941.246 | BJ80: =BI80*Y80 -> 8.9028338 | BK80: =(H80*J80)/AB80 -> 216.69675 | BL80: =BK80*Y80 -> 0.99380251 | BM80: =AC80/H80 -> 0.093457944 | BN80: =BM80*Y80 -> 0.00042861159 | BO80: =I80/AD80 -> 2131.7421 | BP80: =BO80*Z80 -> 11.109819 | BQ80: =(I80*J80)/AB80 -> 237.96139 | BR80: =BQ80*Z80 -> 1.240163 | BS80: =AC80/I80 -> 0.085106383 | BT80: =BS80*Z80 -> 0.00044354167
B81: MASI | M81: =SUM(M4:M80) -> 2.6136727e+11 | N81: =SUM(N4:N80) -> 2.5765837e+11 | O81: =SUM(O4:O80) -> 2.5679537e+11 | P81: =SUM(P4:P80) -> 2.6964712e+11 | Q81: =SUM(Q4:Q80) -> 2.7233424e+11 | R81: =SUM(R4:R80) -> 2.6730448e+11 | S81: =SUM(S4:S80) -> 2.5830673e+11 | T81: =M81/$M$81 -> 1 | U81: =N81/$N$81 -> 1 | V81: =O81/$O$81 -> 1 | W81: =SUM(W4:W80) -> 1 | X81: =SUM(X4:X80) -> 1 | Y81: =SUM(Y4:Y80) -> 1 | Z81: =SUM(Z4:Z80) -> 1 | AF81: =SUM(AF4:AF80) -> 42.59146 | AH81: =SUM(AH4:AH80) -> 6.4335671 | AJ81: =SUM(AJ4:AJ80) -> 0.023867781 | AL81: =SUM(AL4:AL80) -> 42.741778 | AN81: =SUM(AN4:AN80) -> 6.3845461 | AP81: =SUM(AP4:AP80) -> 0.02421135 | AR81: =SUM(AR4:AR80) -> 43.919134 | AT81: =SUM(AT4:AT80) -> 6.4808029 | AV81: =SUM(AV4:AV80) -> 0.024292716 | AX81: =SUM(AX4:AX80) -> 44.025561 | AZ81: =SUM(AZ4:AZ80) -> 6.6082551 | BB81: =SUM(BB4:BB80) -> 0.023134891 | BD81: =SUM(BD4:BD80) -> 44.191078 | BF81: =SUM(BF4:BF80) -> 6.6607942 | BH81: =SUM(BH4:BH80) -> 0.02290662 | BJ81: =SUM(BJ4:BJ80) -> 44.7463 | BL81: =SUM(BL4:BL80) -> 6.5537677 | BN81: =SUM(BN4:BN80) -> 0.023337644 | BP81: =SUM(BP4:BP80) -> 46.05557 | BR81: =SUM(BR4:BR80) -> 6.6483778 | BT81: =SUM(BT4:BT80) -> 0.024150578

Sheet R-R MASI 20
B1: Les cours de clôture | V1: Les rendements
A2: Date | B2: AKDITAL | C2: ALLIANCES | D2: ATTIJARIWAFA BANK | E2: BANK OF AFRICA | F2: BCP | G2: CDM | H2: CFG BANK | I2: CIMENTS DU MAROC | J2: CMGP GROUP | K2: COSUMAR | L2: DOUJA PROM ADDOHA | M2: ITISSALAT AL-MAGHRIB | N2: JET CONTRACTORS | O2: LABEL VIE | P2: LAFARGEHOLCIM MAROC | Q2: RESIDENCES DAR SAADA | R2: SODEP-Marsa Maroc | S2: SONASID | T2: TAQA MOROCCO | U2: TGCC S.A | V2: AKDITAL | W2: ALLIANCES | X2: ATTIJARIWAFA BANK | Y2: BANK OF AFRICA | Z2: BCP | AA2: CDM | AB2: CFG BANK | AC2: CIMENTS DU MAROC | AD2: CMGP GROUP | AE2: COSUMAR | AF2: DOUJA PROM ADDOHA | AG2: ITISSALAT AL-MAGHRIB | AH2: JET CONTRACTORS | AI2: LABEL VIE | AJ2: LAFARGEHOLCIM MAROC | AK2: RESIDENCES DAR SAADA | AL2: SODEP-Marsa Maroc | AM2: SONASID | AN2: TAQA MOROCCO | AO2: TGCC S.A
A3: 45947 | B3: 1235 | C3: 519 | D3: 728 | E3: 225.4 | F3: 280 | G3: 990 | H3: 234 | I3: 1920 | J3: 376.6 | K3: 204 | L3: 36.79 | M3: 115.6 | N3: 2437 | O3: 4690 | P3: 1844 | Q3: 168.1 | R3: 920 | S3: 2415 | T3: 2309 | U3: 900 | V3: =(B3/B4)-1 -> 0.0089869281 | W3: =(C3/C4)-1 -> 0.027926322 | X3: =(D3/D4)-1 -> -0.002739726 | Y3: =(E3/E4)-1 -> 0.0087719298 | Z3: =(F3/F4)-1 -> 0.0035842294 | AA3: =(G3/G4)-1 -> 0 | AB3: =(H3/H4)-1 -> 0.0099266293 | AC3: =(I3/I4)-1 -> -0.034690799 | ... AO3: =(U3/U4)-1 -> 0
A4: 45946 | B4: 1224 | C4: 504.9 | D4: 730 | E4: 223.44 | F4: 279 | G4: 990 | H4: 231.7 | I4: 1989 | J4: 384 | K4: 204.25 | L4: 36 | M4: 115 | N4: 2400 | O4: 4750 | P4: 1860 | Q4: 169.1 | R4: 910 | S4: 2380 | T4: 2340 | U4: 900 | V4: =(B4/B5)-1 -> 0.0032786885 | W4: =(C4/C5)-1 -> 0.0055765784 | X4: =(D4/D5)-1 -> 0.020979021 | Y4: =(E4/E5)-1 -> 0.022187657 | Z4: =(F4/F5)-1 -> -0.001610306 | AA4: =(G4/G5)-1 -> 0 | AB4: =(H4/H5)-1 -> -0.02606137 | AC4: =(I4/I5)-1 -> 0.046842105 | ... AO4: =(U4/U5)-1 -> 0.034482759
A5: 45945 | B5: 1220 | C5: 502.1 | D5: 715 | E5: 218.59 | F5: 279.45 | G5: 990 | H5: 237.9 | I5: 1900 | J5: 368 | K5: 198.9 | L5: 34.91 | M5: 112.95 | N5: 2390 | O5: 4540 | P5: 1837 | Q5: 165 | R5: 903.8 | S5: 2350 | T5: 2340 | U5: 870 | V5: =(B5/B6)-1 -> 0 | W5: =(C5/C6)-1 -> -0.015297117 | X5: =(D5/D6)-1 -> -0.020547945 | Y5: =(E5/E6)-1 -> 0.0092806353 | Z5: =(F5/F6)-1 -> 0.0088447653 | AA5: =(G5/G6)-1 -> -0.01 | AB5: =(H5/H6)-1 -> 0.012340426 | AC5: =(I5/I6)-1 -> 0 | ... AO5: =(U5/U6)-1 -> -0.0057142857
A6: 45944 | B6: 1220 | C6: 509.9 | D6: 730 | E6: 216.58 | F6: 277 | G6: 1000 | H6: 235 | I6: 1900 | J6: 370 | K6: 198 | L6: 35.03 | M6: 113 | N6: 2399 | O6: 4550 | P6: 1806 | Q6: 166.9 | R6: 919 | S6: 2380 | T6: 2300 | U6: 875 | V6: =(B6/B7)-1 -> -0.054263566 | W6: =(C6/C7)-1 -> -0.019423077 | X6: =(D6/D7)-1 -> -0.013246823 | Y6: =(E6/E7)-1 -> -0.053946621 | Z6: =(F6/F7)-1 -> -0.034843206 | AA6: =(G6/G7)-1 -> -0.0039840637 | AB6: =(H6/H7)-1 -> -0.024896266 | AC6: =(I6/I7)-1 -> -0.025641026 | ... AO6: =(U6/U7)-1 -> -0.027669741
A7: 45943 | B7: 1290 | C7: 520 | D7: 739.8 | E7: 228.93 | F7: 287 | G7: 1004 | H7: 241 | I7: 1950 | J7: 384 | K7: 204.05 | L7: 36 | M7: 114.5 | N7: 2440 | O7: 4600 | P7: 1860 | Q7: 173 | R7: 931.1 | S7: 2425 | T7: 2400 | U7: 899.9 | V7: =(B7/B8)-1 -> 0.0038910506 | W7: =(C7/C8)-1 -> 0.0097087379 | X7: =(D7/D8)-1 -> 0.013424658 | Y7: =(E7/E8)-1 -> -0.0063802083 | Z7: =(F7/F8)-1 -> 0.0070175439 | AA7: =(G7/G8)-1 -> 0.013118063 | AB7: =(H7/H8)-1 -> 0.0041666667 | AC7: =(I7/I8)-1 -> 0.0051546392 | ... AO7: =(U7/U8)-1 -> 0.018908514
A8: 45940 | B8: 1285 | C8: 515 | D8: 730 | E8: 230.4 | F8: 285 | G8: 991 | H8: 240 | I8: 1940 | J8: 370 | K8: 204 | L8: 36.15 | M8: 114.5 | N8: 2469 | O8: 4600 | P8: 1800 | Q8: 178 | R8: 935 | S8: 2425 | T8: 2400 | U8: 883.2 | V8: =(B8/B9)-1 -> -0.011538462 | W8: =(C8/C9)-1 -> -0.019047619 | X8: =(D8/D9)-1 -> 0 | Y8: =(E8/E9)-1 -> 0.017757752 | Z8: =(F8/F9)-1 -> 0 | AA8: =(G8/G9)-1 -> -0.0040201005 | AB8: =(H8/H9)-1 -> 0 | AC8: =(I8/I9)-1 -> -0.0046177527 | ... AO8: =(U8/U9)-1 -> -0.018666667
A9: 45939 | B9: 1300 | C9: 525 | D9: 730 | E9: 226.38 | F9: 285 | G9: 995 | H9: 240 | I9: 1949 | J9: 381 | K9: 201 | L9: 36.79 | M9: 115.95 | N9: 2462 | O9: 4600 | P9: 1811 | Q9: 179.7 | R9: 922 | S9: 2390 | T9: 2448 | U9: 900 | V9: =(B9/B10)-1 -> -0.018867925 | W9: =(C9/C10)-1 -> -0.0037950664 | X9: =(D9/D10)-1 -> -0.021447721 | Y9: =(E9/E10)-1 -> -0.041493776 | Z9: =(F9/F10)-1 -> -0.024139702 | AA9: =(G9/G10)-1 -> -0.0089641434 | AB9: =(H9/H10)-1 -> -0.0041493776 | AC9: =(I9/I10)-1 -> 0.0036045314 | ... AO9: =(U9/U10)-1 -> -0.010989011
A10: 45938 | B10: 1325 | C10: 527 | D10: 746 | E10: 236.18 | F10: 292.05 | G10: 1004 | H10: 241 | I10: 1942 | J10: 389.95 | K10: 210 | L10: 37.05 | M10: 116 | N10: 2443 | O10: 4750 | P10: 1870 | Q10: 184 | R10: 935.5 | S10: 2400 | T10: 2450 | U10: 910 | V10: =(B10/B11)-1 -> -0.01266766 | W10: =(C10/C11)-1 -> 0.0038095238 | X10: =(D10/D11)-1 -> -0.0066577896 | Y10: =(E10/E11)-1 -> -0.012295082 | Z10: =(F10/F11)-1 -> 0.00017123288 | AA10: =(G10/G11)-1 -> 0.006012024 | AB10: =(H10/H11)-1 -> -0.012497439 | AC10: =(I10/I11)-1 -> -0.0041025641 | ... AO10: =(U10/U11)-1 -> -0.01194354
A11: 45937 | B11: 1342 | C11: 525 | D11: 751 | E11: 239.12 | F11: 292 | G11: 998 | H11: 244.05 | I11: 1950 | J11: 391.4 | K11: 208 | L11: 37.5 | M11: 117.05 | N11: 2460 | O11: 4700 | P11: 1880 | Q11: 185.9 | R11: 950 | S11: 2411 | T11: 2450 | U11: 921 | V11: =(B11/B12)-1 -> 0.002240478 | W11: =(C11/C12)-1 -> -0.0094339623 | X11: =(D11/D12)-1 -> -0.0066137566 | Y11: =(E11/E12)-1 -> -0.016129032 | Z11: =(F11/F12)-1 -> -0.020134228 | AA11: =(G11/G12)-1 -> -0.028237585 | AB11: =(H11/H12)-1 -> -0.0018404908 | AC11: =(I11/I12)-1 -> -0.025 | ... AO11: =(U11/U12)-1 -> -0.014973262
A12: 45936 | B12: 1339 | C12: 530 | D12: 756 | E12: 243.04 | F12: 298 | G12: 1027 | H12: 244.5 | I12: 2000 | J12: 392 | K12: 213.95 | L12: 38.24 | M12: 117.3 | N12: 2432 | O12: 4700 | P12: 1888 | Q12: 185 | R12: 950 | S12: 2382 | T12: 2425 | U12: 935 | V12: =(B12/B13)-1 -> -0.024763292 | W12: =(C12/C13)-1 -> 0.039215686 | X12: =(D12/D13)-1 -> 0.021621622 | Y12: =(E12/E13)-1 -> 0.029045643 | Z12: =(F12/F13)-1 -> 0.017412086 | AA12: =(G12/G13)-1 -> 0.027 | AB12: =(H12/H13)-1 -> -0.0020408163 | AC12: =(I12/I13)-1 -> 0.01010101 | ... AO12: =(U12/U13)-1 -> 0.021746257
A13: 45933 | B13: 1373 | C13: 510 | D13: 740 | E13: 236.18 | F13: 292.9 | G13: 1000 | H13: 245 | I13: 1980 | J13: 385 | K13: 207.5 | L13: 38.38 | M13: 116.4 | N13: 2439 | O13: 4599 | P13: 1898 | Q13: 173.8 | R13: 936 | S13: 2400 | T13: 2400 | U13: 915.1 | V13: =(B13/B14)-1 -> 0.032330827 | W13: =(C13/C14)-1 -> 0.040816327 | X13: =(D13/D14)-1 -> 0.020830459 | Y13: =(E13/E14)-1 -> -0.024291498 | Z13: =(F13/F14)-1 -> 0.045884663 | AA13: =(G13/G14)-1 -> 0.025641026 | AB13: =(H13/H14)-1 -> 0.042553191 | AC13: =(I13/I14)-1 -> 0.00050530571 | ... AO13: =(U13/U14)-1 -> 0.028202247
A14: 45932 | B14: 1330 | C14: 490 | D14: 724.9 | E14: 242.06 | F14: 280.05 | G14: 975 | H14: 235 | I14: 1979 | J14: 370 | K14: 203 | L14: 37 | M14: 114.1 | N14: 2360 | O14: 4600 | P14: 1878 | Q14: 160 | R14: 915 | S14: 2320 | T14: 2250 | U14: 890 | V14: =(B14/B15)-1 -> 0.0083396513 | W14: =(C14/C15)-1 -> -0.01010101 | X14: =(D14/D15)-1 -> -0.00013793103 | Y14: =(E14/E15)-1 -> 0.046610169 | Z14: =(F14/F15)-1 -> 0.00017857143 | AA14: =(G14/G15)-1 -> -0.0030674847 | AB14: =(H14/H15)-1 -> 0.008583691 | AC14: =(I14/I15)-1 -> 0.041578947 | ... AO14: =(U14/U15)-1 -> 0.011363636
... A209: 45643 | B209: 1059 | C209: 447.9 | D209: 575 | E209: 192.08 | F209: 285.3 | G209: 979.9 | H209: 218 | I209: 1911 | J209: 241.9 | K209: 191.1 | L209: 38 | M209: 86.3 | N209: 1680 | O209: 4099 | P209: 1960 | Q209: 79.45 | R209: 535 | S209: 960 | T209: 1391 | U209: 478 | V209: =(B209/B210)-1 -> -0.0056338028 | W209: =(C209/C210)-1 -> 0.014036676 | X209: =(D209/D210)-1 -> 0.0043668122 | Y209: =(E209/E210)-1 -> 0.018992042 | Z209: =(F209/F210)-1 -> 0 | AA209: =(G209/G210)-1 -> 0.020729167 | AB209: =(H209/H210)-1 -> 0.016317016 | AC209: =(I209/I210)-1 -> -0.019497178 | ... AO209: =(U209/U210)-1 -> 0
A210: 45642 | B210: 1065 | C210: 441.7 | D210: 572.5 | E210: 188.5 | F210: 285.3 | G210: 960 | H210: 214.5 | I210: 1949 | J210: 219.95 | K210: 191 | L210: 37.86 | M210: 86.24 | N210: 1631 | O210: 4085 | P210: 1940 | Q210: 79.9 | R210: 530 | S210: 936 | T210: 1360 | U210: 478
U211: Rendement Moyen | V211: =AVERAGE(V3:V210) -> 0.00084625262 | W211: =AVERAGE(W3:W210) -> 0.0010228972 | X211: =AVERAGE(X3:X210) -> 0.0012367961 | Y211: =AVERAGE(Y3:Y210) -> 0.0010811362 | Z211: =AVERAGE(Z3:Z210) -> 1.6909768e-05 | AA211: =AVERAGE(AA3:AA210) -> 0.00032395039 | AB211: =AVERAGE(AB3:AB210) -> 0.00054858994 | AC211: =AVERAGE(AC3:AC210) -> 0.00016148957 | ... AO211: =AVERAGE(AO3:AO210) -> 0.0033177525
U212: Risque | V212: =SQRT(V213) -> 0.016211792 | W212: =SQRT(W213) -> 0.022162532 | X212: =SQRT(X213) -> 0.012327751 | Y212: =SQRT(Y213) -> 0.020867424 | Z212: =SQRT(Z213) -> 0.01470827 | AA212: =SQRT(AA213) -> 0.018758628 | AB212: =SQRT(AB213) -> 0.01601431 | AC212: =SQRT(AC213) -> 0.02168426 | ... AO212: =SQRT(AO213) -> 0.022821593
U213: Variance | V213: =_xlfn.VAR.S(V3:V210) -> 0.00026282219 | W213: =_xlfn.VAR.S(W3:W210) -> 0.00049117783 | X213: =_xlfn.VAR.S(X3:X210) -> 0.00015197345 | Y213: =_xlfn.VAR.S(Y3:Y210) -> 0.00043544939 | Z213: =_xlfn.VAR.S(Z3:Z210) -> 0.00021633322 | AA213: =_xlfn.VAR.S(AA3:AA210) -> 0.00035188614 | AB213: =_xlfn.VAR.S(AB3:AB210) -> 0.00025645812 | AC213: =_xlfn.VAR.S(AC3:AC210) -> 0.00047020711 | ... AO213: =_xlfn.VAR.S(AO3:AO210) -> 0.0005208251

Sheet Masi 20
AE2: 45933 | AK2: 45940 | AQ2: 45947 | AW2: 45954 | BC2: 45961 | BI2: 45968 | BO2: 45975
B3: ENTREPRISE | C3: Cours 03/10/25 | D3: Cours 10/10/25 | E3: Cours 17/10/25 | F3: Cours 24/10/25 | G3: Cours 31/10/25 | H3: Cours 07/11/25 | I3: Cours 14/11/25 | J3: Nbre de titres | K3: Capitalisation Globale 14/11/25 | L3: Facteurs flottants | M3: Capitalisation flottante 03/10/25 | N3: Capitalisation flottante 10/10/25 | O3: Capitalisation flottante17/10/25 | P3: Capitalisation flottante 24/10/25 | Q3: Capitalisation flottante 31/10/25 | R3: Capitalisation flottante 07/11/25 | S3: Capitalisation flottante 14/11/25 | T3: poids 03/10/25 | U3: poids 10/10/25 | V3: poids 17/10/25 | W3: poids 24/10/25 | X3: poids 31/10/25 | Y3: poids 07/11/25 | Z3: poids 14/11/25 | AA3: Rnet | AB3: fondspropres | AC3: dividende par action | AD3: BPA | AE3: PER | AF3: PER*POIDS | AG3: PBR | AH3: PBR*POID | AI3: DY | AJ3: DY*POIDS | AK3: PER | AL3: PER*POIDS | AM3: PBR | AN3: PBR*POID | AO3: DY | AP3: DY*POIDS | AQ3: PER | AR3: PER*POIDS | AS3: PBR | AT3: PBR*POID | AU3: DY | AV3: DY*POIDS | AW3: PER | AX3: PER*POIDS | AY3: PBR | AZ3: PBR*POID | BA3: DY | BB3: DY*POIDS | BC3: PER | BD3: PER*POIDS | BE3: PBR | BF3: PBR*POID | BG3: DY | BH3: DY*POIDS | BI3: PER | BJ3: PER*POIDS | BK3: PBR | BL3: PBR*POID | BM3: DY | BN3: DY*POIDS | BO3: PER | BP3: PER*POIDS | BQ3: PBR | BR3: PBR*POID | BS3: DY | BT3: DY*POIDS
A4: 1 | B4: AKDITAL | C4: 1373 | D4: 1285 | E4: 1235 | F4: 1370 | G4: 1440 | H4: 1390 | I4: 1330 | J4: 14159207 | K4: =I4*J4 -> 18831745310 | L4: 0.4524 | M4: =(C4*J4)*L4 -> 8.7949235e+09 | N4: =(D4*J4)*L4 -> 8.2312284e+09 | O4: =(E4*J4)*L4 -> 7.9109472e+09 | P4: =F4*J4*L4 -> 8.7757066e+09 | Q4: =G4*J4*L4 -> 9.2241004e+09 | R4: =H4*J4*L4 -> 8.9038191e+09 | S4: =I4*J4*L4 -> 8.5194816e+09 | T4: =M4/$M$24 -> 0.042861286 | U4: =N4/$N$24 -> 0.040852531 | V4: =O4/$O$24 -> 0.039404546 | W4: =P4/$P$24 -> 0.041282943 | X4: =Q4/$Q$24 -> 0.042960284 | Y4: =R4/$R$24 -> 0.042261641 | Z4: =S4/$S$24 -> 0.0420111 | AA4: 347553992 | AB4: 2638508203 | AC4: 10 | AD4: =AA4/J4 -> 24.546148 | AE4: =C4/AD4 -> 55.935457 | AF4: =AE4*T4 -> 2.3974656 | AG4: =(C4*J4)/AB4 -> 7.3680238 | AH4: =AG4*T4 -> 0.31580298 | AI4: =AC4/C4 -> 0.0072833212 | AJ4: =AI4*T4 -> 0.00031217252 | AK4: =D4/AD4 -> 52.350373 | AL4: =AK4*U4 -> 2.1386452 | AM4: =(D4*J4)/AB4 -> 6.8957834 | AN4: =AM4*U4 -> 0.28171021 | AO4: =AC4/D4 -> 0.0077821012 | AP4: =AO4*U4 -> 0.00031791853 | AQ4: =E4/AD4 -> 50.313393 | AR4: =AQ4*V4 -> 1.9825764 | AS4: =(E4*J4)/AB4 -> 6.627465 | AT4: =AS4*V4 -> 0.26115225 | AU4: =AC4/E4 -> 0.008097166 | AV4: =AU4*V4 -> 0.00031906515 | AW4: =F4/AD4 -> 55.813238 | AX4: =AW4*W4 -> 2.3041347 | AY4: =(F4*J4)/AB4 -> 7.3519247 | AZ4: =AY4*W4 -> 0.30350909 | BA4: =AC4/F4 -> 0.0072992701 | BB4: =BA4*W4 -> 0.00030133535 | BC4: =G4/AD4 -> 58.665009 | BD4: =BC4*X4 -> 2.5202654 | BE4: =(G4*J4)/AB4 -> 7.7275705 | BF4: =BE4*X4 -> 0.33197862 | BG4: =AC4/G4 -> 0.0069444444 | BH4: =BG4*X4 -> 0.0002983353 | BI4: =H4/AD4 -> 56.62803 | BJ4: =BI4*Y4 -> 2.3931934 | BK4: =(H4*J4)/AB4 -> 7.4592521 | BL4: =BK4*Y4 -> 0.31524023 | BM4: =AC4/H4 -> 0.0071942446 | BN4: =BM4*Y4 -> 0.00030404058 | BO4: =I4/AD4 -> 54.183654 | BP4: =BO4*Z4 -> 2.2763149 | BQ4: =(I4*J4)/AB4 -> 7.1372699 | BR4: =BQ4*Z4 -> 0.29984456 | BS4: =AC4/I4 -> 0.007518797 | BT4: =BS4*Z4 -> 0.00031587293
A5: 2 | B5: ALLIANCES | C5: 510 | D5: 515 | E5: 519 | F5: 560 | G5: 617.9 | H5: 618.1 | I5: 595 | J5: 22078588 | K5: =I5*J5 -> 13136759860 | L5: 0.38 | M5: =(C5*J5)*L5 -> 4.2788304e+09 | N5: =(D5*J5)*L5 -> 4.3207797e+09 | O5: =(E5*J5)*L5 -> 4.3543391e+09 | P5: =F5*J5*L5 -> 4.6983235e+09 | Q5: =G5*J5*L5 -> 5.1840966e+09 | R5: =H5*J5*L5 -> 5.1857746e+09 | S5: =I5*J5*L5 -> 4.9919687e+09 | T5: =M5/$M$24 -> 0.020852504 | U5: =N5/$N$24 -> 0.021444525 | V5: =O5/$O$24 -> 0.021689028 | W5: =P5/$P$24 -> 0.022101995 | X5: =Q5/$Q$24 -> 0.024144388 | Y5: =R5/$R$24 -> 0.024614083 | Z5: =S5/$S$24 -> 0.024616298 | AA5: 301915000 | AB5: 3668286000 | AC5: 3.6 | AD5: =AA5/J5 -> 13.674561 | AE5: =C5/AD5 -> 37.29553 | AF5: =AE5*T5 -> 0.77770517 | AG5: =(C5*J5)/AB5 -> 3.0695752 | AH5: =AG5*T5 -> 0.064008329 | AI5: =AC5/C5 -> 0.0070588235 | AJ5: =AI5*T5 -> 0.00014719414 | AK5: =D5/AD5 -> 37.661172 | AL5: =AK5*U5 -> 0.80762596 | AM5: =(D5*J5)/AB5 -> 3.0996691 | AN5: =AM5*U5 -> 0.066470933 | AO5: =AC5/D5 -> 0.0069902913 | AP5: =AO5*U5 -> 0.00014990348 | AQ5: =E5/AD5 -> 37.953686 | AR5: =AQ5*V5 -> 0.82317857 | AS5: =(E5*J5)/AB5 -> 3.1237442 | AT5: =AS5*V5 -> 0.067750976 | AU5: =AC5/E5 -> 0.0069364162 | AV5: =AU5*V5 -> 0.00015044413 | AW5: =F5/AD5 -> 40.951954 | AX5: =AW5*W5 -> 0.90511989 | AY5: =(F5*J5)/AB5 -> 3.370514 | AZ5: =AY5*W5 -> 0.074495084 | BA5: =AC5/F5 -> 0.0064285714 | BB5: =BA5*W5 -> 0.00014208425 | BC5: =G5/AD5 -> 45.186094 | BD5: =BC5*X5 -> 1.0909906 | BE5: =(G5*J5)/AB5 -> 3.7190011 | BF5: =BE5*X5 -> 0.089793006 | BG5: =AC5/G5 -> 0.0058261855 | BH5: =BG5*X5 -> 0.00014066969 | BI5: =H5/AD5 -> 45.20072 | BJ5: =BI5*Y5 -> 1.1125743 | BK5: =(H5*J5)/AB5 -> 3.7202048 | BL5: =BK5*Y5 -> 0.091569431 | BM5: =AC5/H5 -> 0.0058243003 | BN5: =BM5*Y5 -> 0.00014335981 | BO5: =I5/AD5 -> 43.511451 | BP5: =BO5*Z5 -> 1.0710909 | BQ5: =(I5*J5)/AB5 -> 3.5811711 | BR5: =BQ5*Z5 -> 0.088155175 | BS5: =AC5/I5 -> 0.0060504202 | BT5: =BS5*Z5 -> 0.00014893895
A6: 3 | B6: ATTIJARIWAFA BANK | C6: 740 | D6: 730 | E6: 728 | F6: 779.9 | G6: 777 | H6: 766 | I6: 736 | J6: 215140839 | K6: =I6*J6 -> 158343657504 | L6: 0.2907 | M6: =(C6*J6)*L6 -> 4.6280667e+10 | N6: =(D6*J6)*L6 -> 4.5655253e+10 | O6: =(E6*J6)*L6 -> 4.553017e+10 | P6: =F6*J6*L6 -> 4.8776071e+10 | Q6: =G6*J6*L6 -> 4.85947e+10 | R6: =H6*J6*L6 -> 4.7906744e+10 | S6: =I6*J6*L6 -> 4.6030501e+10 | T6: =M6/$M$24 -> 0.22554476 | U6: =N6/$N$24 -> 0.22659226 | V6: =O6/$O$24 -> 0.22678645 | W6: =P6/$P$24 -> 0.22945386 | X6: =Q6/$Q$24 -> 0.22632474 | Y6: =R6/$R$24 -> 0.22738755 | Z6: =S6/$S$24 -> 0.2269847 | AA6: 9504486000 | AB6: 72502834000 | AC6: 19 | AD6: =AA6/J6 -> 44.177972 | AE6: =C6/AD6 -> 16.750429 | AF6: =AE6*T6 -> 3.7779716 | AG6: =(C6*J6)/AB6 -> 2.1958345 | AH6: =AG6*T6 -> 0.49525896 | AI6: =AC6/C6 -> 0.025675676 | AJ6: =AI6*T6 -> 0.0057910142 | AK6: =D6/AD6 -> 16.524072 | AL6: =AK6*U6 -> 3.7442268 | AM6: =(D6*J6)/AB6 -> 2.166161 | AN6: =AM6*U6 -> 0.49083532 | AO6: =AC6/D6 -> 0.026027397 | AP6: =AO6*U6 -> 0.0058976067 | AQ6: =E6/AD6 -> 16.478801 | AR6: =AQ6*V6 -> 3.7371688 | AS6: =(E6*J6)/AB6 -> 2.1602263 | AT6: =AS6*V6 -> 0.48991007 | AU6: =AC6/E6 -> 0.026098901 | AV6: =AU6*V6 -> 0.0059188772 | AW6: =F6/AD6 -> 17.653594 | AX6: =AW6*W6 -> 4.0506854 | AY6: =(F6*J6)/AB6 -> 2.3142315 | AZ6: =AY6*W6 -> 0.53100935 | BA6: =AC6/F6 -> 0.024362098 | BB6: =BA6*W6 -> 0.0055899774 | BC6: =G6/AD6 -> 17.587951 | BD6: =BC6*X6 -> 3.9805884 | BE6: =(G6*J6)/AB6 -> 2.3056262 | BF6: =BE6*X6 -> 0.52182025 | BG6: =AC6/G6 -> 0.024453024 | BH6: =BG6*X6 -> 0.0055343244 | BI6: =H6/AD6 -> 17.338958 | BJ6: =BI6*Y6 -> 3.9426632 | BK6: =(H6*J6)/AB6 -> 2.2729854 | BL6: =BK6*Y6 -> 0.51684859 | BM6: =AC6/H6 -> 0.024804178 | BN6: =BM6*Y6 -> 0.0056401612 | BO6: =I6/AD6 -> 16.659886 | BP6: =BO6*Z6 -> 3.7815393 | BQ6: =(I6*J6)/AB6 -> 2.1839651 | BR6: =BQ6*Z6 -> 0.49572666 | BS6: =AC6/I6 -> 0.025815217 | BT6: =BS6*Z6 -> 0.0058596594
A7: 4 | B7: BANK OF AFRICA | C7: 241 | D7: 235.1 | E7: 230 | F7: 245 | G7: 242 | H7: 235 | I7: 227 | J7: 215786333 | K7: =I7*J7 -> 48983497591 | L7: 0.2124 | M7: =(C7*J7)*L7 -> 1.1045757e+10 | N7: =(D7*J7)*L7 -> 1.0775342e+10 | O7: =(E7*J7)*L7 -> 1.0541594e+10 | P7: =F7*J7*L7 -> 1.1229089e+10 | Q7: =G7*J7*L7 -> 1.109159e+10 | R7: =H7*J7*L7 -> 1.0770759e+10 | S7: =I7*J7*L7 -> 1.0404095e+10 | T7: =M7/$M$24 -> 0.053830526 | U7: =N7/$N$24 -> 0.053479261 | V7: =O7/$O$24 -> 0.052507837 | W7: =P7/$P$24 -> 0.05282422 | X7: =Q7/$Q$24 -> 0.051657923 | Y7: =R7/$R$24 -> 0.051123001 | Z7: =S7/$S$24 -> 0.051304468 | AA7: 3427420000 | AB7: 36814698000 | AC7: 5 | AD7: =AA7/J7 -> 15.883397 | AE7: =C7/AD7 -> 15.173077 | AF7: =AE7*T7 -> 0.8167747 | AG7: =(C7*J7)/AB7 -> 1.4126017 | AH7: =AG7*T7 -> 0.076041095 | AI7: =AC7/C7 -> 0.020746888 | AJ7: =AI7*T7 -> 0.0011168159 | AK7: =D7/AD7 -> 14.80162 | AL7: =AK7*U7 -> 0.79157967 | AM7: =(D7*J7)/AB7 -> 1.3780194 | AN7: =AM7*U7 -> 0.073695457 | AO7: =AC7/D7 -> 0.021267546 | AP7: =AO7*U7 -> 0.0011373726 | AQ7: =E7/AD7 -> 14.48053 | AR7: =AQ7*V7 -> 0.76034128 | AS7: =(E7*J7)/AB7 -> 1.3481261 | AT7: =AS7*V7 -> 0.070787187 | AU7: =AC7/E7 -> 0.02173913 | AV7: =AU7*V7 -> 0.0011414747 | AW7: =F7/AD7 -> 15.424912 | AX7: =AW7*W7 -> 0.81480894 | AY7: =(F7*J7)/AB7 -> 1.4360474 | AZ7: =AY7*W7 -> 0.075858084 | BA7: =AC7/F7 -> 0.020408163 | BB7: =BA7*W7 -> 0.0010780453 | BC7: =G7/AD7 -> 15.236035 | BD7: =BC7*X7 -> 0.78706194 | BE7: =(G7*J7)/AB7 -> 1.4184632 | BF7: =BE7*X7 -> 0.07327486 | BG7: =AC7/G7 -> 0.020661157 | BH7: =BG7*X7 -> 0.0010673124 | BI7: =H7/AD7 -> 14.795324 | BJ7: =BI7*Y7 -> 0.75638134 | BK7: =(H7*J7)/AB7 -> 1.3774332 | BL7: =BK7*Y7 -> 0.07041852 | BM7: =AC7/H7 -> 0.021276596 | BN7: =BM7*Y7 -> 0.0010877234 | BO7: =I7/AD7 -> 14.291653 | BP7: =BO7*Z7 -> 0.73322565 | BQ7: =(I7*J7)/AB7 -> 1.3305419 | BR7: =BQ7*Z7 -> 0.068262743 | BS7: =AC7/I7 -> 0.022026432 | BT7: =BS7*Z7 -> 0.0011300544
